Workbook

Sheet DATA
A1: CustomerID | B1: Surname | C1: CreditScore | D1: Geography | E1: Gender | F1: Age | G1: Tenure | H1: Balance | I1: NumOfProducts | J1: HasCrCard | K1: IsActiveMember | L1: EstimatedSalary | M1: Churn | N1: z-score of Balance | O1: z-score of Salary | P1: Age Category | Q1: Tenure Period | R1: CS Category | S1: Gender Category | T1: Geography Category
A2: 1 | B2: Davis | C2: 764 | D2: Germany | E2: Male | F2: 20 | G2: 7 | H2: 119274.87 | I2: 3 | J2: 1 | K2: 0 | L2: 107886.77 | M2: 0 | N2: =(H2-$X$4)/$X$7 -> -0.12663164 | O2: =(L2-$Y$5)/$Y$8 -> 0.62719441 | P2: {=_xlfn.IFS(AND(F2>15,F2<=30), "Youngsters", AND(F2>30,F2<=50), "Adults", AND(F2>50,F2<=70),"Old person", AND(F2>70, F2<92), "Senior Citizens")} -> Youngsters | Q2: {=_xlfn.IFS(G2=0,"No Tenure Period",AND(G2>0,G2<=3),"Less Tenure Period",AND(G2>3,G2<=7),"More Tenure Period",AND(G2>7,G2<=10),"Large Tenure Period")} -> More Tenure Period | R2: {=_xlfn.IFS(AND(C2>300,C2<=525),"1 Star",AND(C2>525,C2<=600),"2 Star",AND(C2>600,C2<=700),"3 Star",AND(C2>700,C2<=750),"4 Star",AND(C2>750,C2<=900),"5 Star")} -> 5 Star | S2: {=_xlfn.IFS(E2="Male",1,E2="Female",2)} -> 1 | T2: {=_xlfn.IFS(D2="France",1,D2="Germany",2,D2="Spain",3)} -> 2
A3: 2 | B3: Smith | C3: 365 | D3: Spain | E3: Female | F3: 64 | G3: 3 | H3: 203737.4 | I3: 3 | J3: 1 | K3: 1 | L3: 52848.11 | M3: 0 | N3: =(H3-$X$4)/$X$7 -> 1.0469073 | O3: =(L3-$Y$5)/$Y$8 -> -0.71774907 | P3: {=_xlfn.IFS(AND(F3>15,F3<=30), "Youngsters", AND(F3>30,F3<=50), "Adults", AND(F3>50,F3<=70),"Old person", AND(F3>70, F3<92), "Senior Citizens")} -> Old person | Q3: {=_xlfn.IFS(G3=0,"No Tenure Period",AND(G3>0,G3<=3),"Less Tenure Period",AND(G3>3,G3<=7),"More Tenure Period",AND(G3>7,G3<=10),"Large Tenure Period")} -> Less Tenure Period | R3: {=_xlfn.IFS(AND(C3>300,C3<=525),"1 Star",AND(C3>525,C3<=600),"2 Star",AND(C3>600,C3<=700),"3 Star",AND(C3>700,C3<=750),"4 Star",AND(C3>750,C3<=900),"5 Star")} -> 1 Star | S3: {=_xlfn.IFS(E3="Male",1,E3="Female",2)} -> 2 | T3: {=_xlfn.IFS(D3="France",1,D3="Germany",2,D3="Spain",3)} -> 3
A4: 3 | B4: Jones | C4: 519 | D4: Germany | E4: Male | F4: 69 | G4: 6 | H4: 146780.5 | I4: 3 | J4: 0 | K4: 0 | L4: 94395.02 | M4: 0 | N4: =(H4-$X$4)/$X$7 -> 0.25553696 | O4: =(L4-$Y$5)/$Y$8 -> 0.2975054 | P4: {=_xlfn.IFS(AND(F4>15,F4<=30), "Youngsters", AND(F4>30,F4<=50), "Adults", AND(F4>50,F4<=70),"Old person", AND(F4>70, F4<92), "Senior Citizens")} -> Old person | Q4: {=_xlfn.IFS(G4=0,"No Tenure Period",AND(G4>0,G4<=3),"Less Tenure Period",AND(G4>3,G4<=7),"More Tenure Period",AND(G4>7,G4<=10),"Large Tenure Period")} -> More Tenure Period | R4: {=_xlfn.IFS(AND(C4>300,C4<=525),"1 Star",AND(C4>525,C4<=600),"2 Star",AND(C4>600,C4<=700),"3 Star",AND(C4>700,C4<=750),"4 Star",AND(C4>750,C4<=900),"5 Star")} -> 1 Star | S4: {=_xlfn.IFS(E4="Male",1,E4="Female",2)} -> 1 | T4: {=_xlfn.IFS(D4="France",1,D4="Germany",2,D4="Spain",3)} -> 2 | W4: Average of Balance | X4: =AVERAGE(H2:H500) -> 128388.87
A5: 4 | B5: Jones | C5: 516 | D5: Germany | E5: Female | F5: 59 | G5: 0 | H5: 23572.03 | I5: 1 | J5: 1 | K5: 0 | L5: 146739.55 | M5: 0 | N5: =(H5-$X$4)/$X$7 -> -1.4563456 | O5: =(L5-$Y$5)/$Y$8 -> 1.5766142 | P5: {=_xlfn.IFS(AND(F5>15,F5<=30), "Youngsters", AND(F5>30,F5<=50), "Adults", AND(F5>50,F5<=70),"Old person", AND(F5>70, F5<92), "Senior Citizens")} -> Old person | Q5: {=_xlfn.IFS(G5=0,"No Tenure Period",AND(G5>0,G5<=3),"Less Tenure Period",AND(G5>3,G5<=7),"More Tenure Period",AND(G5>7,G5<=10),"Large Tenure Period")} -> No Tenure Period | R5: {=_xlfn.IFS(AND(C5>300,C5<=525),"1 Star",AND(C5>525,C5<=600),"2 Star",AND(C5>600,C5<=700),"3 Star",AND(C5>700,C5<=750),"4 Star",AND(C5>750,C5<=900),"5 Star")} -> 1 Star | S5: {=_xlfn.IFS(E5="Male",1,E5="Female",2)} -> 2 | T5: {=_xlfn.IFS(D5="France",1,D5="Germany",2,D5="Spain",3)} -> 2 | W5: Average of Salary | X5: =AVERAGE(L5:L500) -> 82203.234 | Y5: =AVERAGE(L2:L500) -> 82220.309
A6: 5 | B6: Wilson | C6: 659 | D6: Spain | E6: Female | F6: 21 | G6: 2 | H6: 7463.43 | I6: 1 | J6: 1 | K6: 1 | L6: 16036.55 | M6: 0 | N6: =(H6-$X$4)/$X$7 -> -1.6801617 | O6: =(L6-$Y$5)/$Y$8 -> -1.6172889 | P6: {=_xlfn.IFS(AND(F6>15,F6<=30), "Youngsters", AND(F6>30,F6<=50), "Adults", AND(F6>50,F6<=70),"Old person", AND(F6>70, F6<92), "Senior Citizens")} -> Youngsters | Q6: {=_xlfn.IFS(G6=0,"No Tenure Period",AND(G6>0,G6<=3),"Less Tenure Period",AND(G6>3,G6<=7),"More Tenure Period",AND(G6>7,G6<=10),"Large Tenure Period")} -> Less Tenure Period | R6: {=_xlfn.IFS(AND(C6>300,C6<=525),"1 Star",AND(C6>525,C6<=600),"2 Star",AND(C6>600,C6<=700),"3 Star",AND(C6>700,C6<=750),"4 Star",AND(C6>750,C6<=900),"5 Star")} -> 3 Star | S6: {=_xlfn.IFS(E6="Male",1,E6="Female",2)} -> 2 | T6: {=_xlfn.IFS(D6="France",1,D6="Germany",2,D6="Spain",3)} -> 3
A7: 6 | B7: Taylor | C7: 777 | D7: Spain | E7: Female | F7: 34 | G7: 0 | H7: 127812.9 | I7: 4 | J7: 1 | K7: 0 | L7: 65189.1 | M7: 0 | N7: =(H7-$X$4)/$X$7 -> -0.0080025842 | O7: =(L7-$Y$5)/$Y$8 -> -0.41618042 | P7: {=_xlfn.IFS(AND(F7>15,F7<=30), "Youngsters", AND(F7>30,F7<=50), "Adults", AND(F7>50,F7<=70),"Old person", AND(F7>70, F7<92), "Senior Citizens")} -> Adults | Q7: {=_xlfn.IFS(G7=0,"No Tenure Period",AND(G7>0,G7<=3),"Less Tenure Period",AND(G7>3,G7<=7),"More Tenure Period",AND(G7>7,G7<=10),"Large Tenure Period")} -> No Tenure Period | R7: {=_xlfn.IFS(AND(C7>300,C7<=525),"1 Star",AND(C7>525,C7<=600),"2 Star",AND(C7>600,C7<=700),"3 Star",AND(C7>700,C7<=750),"4 Star",AND(C7>750,C7<=900),"5 Star")} -> 5 Star | S7: {=_xlfn.IFS(E7="Male",1,E7="Female",2)} -> 2 | T7: {=_xlfn.IFS(D7="France",1,D7="Germany",2,D7="Spain",3)} -> 3 | W7: Std.dev. Of Balance | X7: =_xlfn.STDEV.S(H2:H500) -> 71972.5
A8: 7 | B8: Jones | C8: 432 | D8: Germany | E8: Female | F8: 81 | G8: 10 | H8: 136164.96 | I8: 4 | J8: 0 | K8: 0 | L8: 135962.88 | M8: 0 | N8: =(H8-$X$4)/$X$7 -> 0.10804257 | O8: =(L8-$Y$5)/$Y$8 -> 1.3132718 | P8: {=_xlfn.IFS(AND(F8>15,F8<=30), "Youngsters", AND(F8>30,F8<=50), "Adults", AND(F8>50,F8<=70),"Old person", AND(F8>70, F8<92), "Senior Citizens")} -> Senior Citizens | Q8: {=_xlfn.IFS(G8=0,"No Tenure Period",AND(G8>0,G8<=3),"Less Tenure Period",AND(G8>3,G8<=7),"More Tenure Period",AND(G8>7,G8<=10),"Large Tenure Period")} -> Large Tenure Period | R8: {=_xlfn.IFS(AND(C8>300,C8<=525),"1 Star",AND(C8>525,C8<=600),"2 Star",AND(C8>600,C8<=700),"3 Star",AND(C8>700,C8<=750),"4 Star",AND(C8>750,C8<=900),"5 Star")} -> 1 Star | S8: {=_xlfn.IFS(E8="Male",1,E8="Female",2)} -> 2 | T8: {=_xlfn.IFS(D8="France",1,D8="Germany",2,D8="Spain",3)} -> 2 | W8: Std.dev. Of Salary | X8: =_xlfn.STDEV.S(L5:L500) -> 41005.363 | Y8: =_xlfn.STDEV.S(L2:L500) -> 40922.656
A9: 8 | B9: Davis | C9: 741 | D9: France | E9: Male | F9: 82 | G9: 5 | H9: 204042.02 | I9: 2 | J9: 1 | K9: 1 | L9: 92581.54 | M9: 1 | N9: =(H9-$X$4)/$X$7 -> 1.0511397 | O9: =(L9-$Y$5)/$Y$8 -> 0.25319059 | P9: {=_xlfn.IFS(AND(F9>15,F9<=30), "Youngsters", AND(F9>30,F9<=50), "Adults", AND(F9>50,F9<=70),"Old person", AND(F9>70, F9<92), "Senior Citizens")} -> Senior Citizens | Q9: {=_xlfn.IFS(G9=0,"No Tenure Period",AND(G9>0,G9<=3),"Less Tenure Period",AND(G9>3,G9<=7),"More Tenure Period",AND(G9>7,G9<=10),"Large Tenure Period")} -> More Tenure Period | R9: {=_xlfn.IFS(AND(C9>300,C9<=525),"1 Star",AND(C9>525,C9<=600),"2 Star",AND(C9>600,C9<=700),"3 Star",AND(C9>700,C9<=750),"4 Star",AND(C9>750,C9<=900),"5 Star")} -> 4 Star | S9: {=_xlfn.IFS(E9="Male",1,E9="Female",2)} -> 1 | T9: {=_xlfn.IFS(D9="France",1,D9="Germany",2,D9="Spain",3)} -> 1
A10: 9 | B10: Williams | C10: 570 | D10: Germany | E10: Female | F10: 31 | G10: 1 | H10: 182609.21 | I10: 2 | J10: 0 | K10: 1 | L10: 141848.51 | M10: 1 | N10: =(H10-$X$4)/$X$7 -> 0.75334807 | O10: =(L10-$Y$5)/$Y$8 -> 1.4570951 | P10: {=_xlfn.IFS(AND(F10>15,F10<=30), "Youngsters", AND(F10>30,F10<=50), "Adults", AND(F10>50,F10<=70),"Old person", AND(F10>70, F10<92), "Senior Citizens")} -> Adults | Q10: {=_xlfn.IFS(G10=0,"No Tenure Period",AND(G10>0,G10<=3),"Less Tenure Period",AND(G10>3,G10<=7),"More Tenure Period",AND(G10>7,G10<=10),"Large Tenure Period")} -> Less Tenure Period | R10: {=_xlfn.IFS(AND(C10>300,C10<=525),"1 Star",AND(C10>525,C10<=600),"2 Star",AND(C10>600,C10<=700),"3 Star",AND(C10>700,C10<=750),"4 Star",AND(C10>750,C10<=900),"5 Star")} -> 2 Star | S10: {=_xlfn.IFS(E10="Male",1,E10="Female",2)} -> 2 | T10: {=_xlfn.IFS(D10="France",1,D10="Germany",2,D10="Spain",3)} -> 2 | W10: People who have churn | X10: =COUNTIF(M2:M500,"1") -> 272
A11: 10 | B11: Brown | C11: 671 | D11: France | E11: Female | F11: 56 | G11: 7 | H11: 56345.73 | I11: 2 | J11: 0 | K11: 0 | L11: 143065.1 | M11: 1 | N11: =(H11-$X$4)/$X$7 -> -1.0009814 | O11: =(L11-$Y$5)/$Y$8 -> 1.4868241 | P11: {=_xlfn.IFS(AND(F11>15,F11<=30), "Youngsters", AND(F11>30,F11<=50), "Adults", AND(F11>50,F11<=70),"Old person", AND(F11>70, F11<92), "Senior Citizens")} -> Old person | Q11: {=_xlfn.IFS(G11=0,"No Tenure Period",AND(G11>0,G11<=3),"Less Tenure Period",AND(G11>3,G11<=7),"More Tenure Period",AND(G11>7,G11<=10),"Large Tenure Period")} -> More Tenure Period | R11: {=_xlfn.IFS(AND(C11>300,C11<=525),"1 Star",AND(C11>525,C11<=600),"2 Star",AND(C11>600,C11<=700),"3 Star",AND(C11>700,C11<=750),"4 Star",AND(C11>750,C11<=900),"5 Star")} -> 3 Star | S11: {=_xlfn.IFS(E11="Male",1,E11="Female",2)} -> 2 | T11: {=_xlfn.IFS(D11="France",1,D11="Germany",2,D11="Spain",3)} -> 1 | W11: People who have not churn | X11: =COUNTIF(M2:M500,"0") -> 227
A12: 11 | B12: Wilson | C12: 519 | D12: France | E12: Female | F12: 22 | G12: 10 | H12: 198399.26 | I12: 3 | J12: 1 | K12: 0 | L12: 125839.96 | M12: 1 | N12: =(H12-$X$4)/$X$7 -> 0.97273812 | O12: =(L12-$Y$5)/$Y$8 -> 1.0659047 | P12: {=_xlfn.IFS(AND(F12>15,F12<=30), "Youngsters", AND(F12>30,F12<=50), "Adults", AND(F12>50,F12<=70),"Old person", AND(F12>70, F12<92), "Senior Citizens")} -> Youngsters | Q12: {=_xlfn.IFS(G12=0,"No Tenure Period",AND(G12>0,G12<=3),"Less Tenure Period",AND(G12>3,G12<=7),"More Tenure Period",AND(G12>7,G12<=10),"Large Tenure Period")} -> Large Tenure Period | R12: {=_xlfn.IFS(AND(C12>300,C12<=525),"1 Star",AND(C12>525,C12<=600),"2 Star",AND(C12>600,C12<=700),"3 Star",AND(C12>700,C12<=750),"4 Star",AND(C12>750,C12<=900),"5 Star")} -> 1 Star | S12: {=_xlfn.IFS(E12="Male",1,E12="Female",2)} -> 2 | T12: {=_xlfn.IFS(D12="France",1,D12="Germany",2,D12="Spain",3)} -> 1
A13: 12 | B13: Miller | C13: 672 | D13: Germany | E13: Male | F13: 21 | G13: 3 | H13: 157278.91 | I13: 3 | J13: 0 | K13: 0 | L13: 58708.71 | M13: 1 | N13: =(H13-$X$4)/$X$7 -> 0.40140393 | O13: =(L13-$Y$5)/$Y$8 -> -0.57453745 | P13: {=_xlfn.IFS(AND(F13>15,F13<=30), "Youngsters", AND(F13>30,F13<=50), "Adults", AND(F13>50,F13<=70),"Old person", AND(F13>70, F13<92), "Senior Citizens")} -> Youngsters | Q13: {=_xlfn.IFS(G13=0,"No Tenure Period",AND(G13>0,G13<=3),"Less Tenure Period",AND(G13>3,G13<=7),"More Tenure Period",AND(G13>7,G13<=10),"Large Tenure Period")} -> Less Tenure Period | R13: {=_xlfn.IFS(AND(C13>300,C13<=525),"1 Star",AND(C13>525,C13<=600),"2 Star",AND(C13>600,C13<=700),"3 Star",AND(C13>700,C13<=750),"4 Star",AND(C13>750,C13<=900),"5 Star")} -> 3 Star | S13: {=_xlfn.IFS(E13="Male",1,E13="Female",2)} -> 1 | T13: {=_xlfn.IFS(D13="France",1,D13="Germany",2,D13="Spain",3)} -> 2
A14: 13 | B14: Moore | C14: 464 | D14: Spain | E14: Female | F14: 37 | G14: 2 | H14: 58317.75 | I14: 3 | J14: 0 | K14: 0 | L14: 13740.96 | M14: 0 | N14: =(H14-$X$4)/$X$7 -> -0.9735818 | O14: =(L14-$Y$5)/$Y$8 -> -1.6733847 | P14: {=_xlfn.IFS(AND(F14>15,F14<=30), "Youngsters", AND(F14>30,F14<=50), "Adults", AND(F14>50,F14<=70),"Old person", AND(F14>70, F14<92), "Senior Citizens")} -> Adults | Q14: {=_xlfn.IFS(G14=0,"No Tenure Period",AND(G14>0,G14<=3),"Less Tenure Period",AND(G14>3,G14<=7),"More Tenure Period",AND(G14>7,G14<=10),"Large Tenure Period")} -> Less Tenure Period | R14: {=_xlfn.IFS(AND(C14>300,C14<=525),"1 Star",AND(C14>525,C14<=600),"2 Star",AND(C14>600,C14<=700),"3 Star",AND(C14>700,C14<=750),"4 Star",AND(C14>750,C14<=900),"5 Star")} -> 1 Star | S14: {=_xlfn.IFS(E14="Male",1,E14="Female",2)} -> 2 | T14: {=_xlfn.IFS(D14="France",1,D14="Germany",2,D14="Spain",3)} -> 3 | W14: Churn
A15: 14 | B15: Moore | C15: 698 | D15: Germany | E15: Male | F15: 34 | G15: 3 | H15: 128968.35 | I15: 1 | J15: 0 | K15: 0 | L15: 143532.82 | M15: 1 | N15: =(H15-$X$4)/$X$7 -> 0.0080514642 | O15: =(L15-$Y$5)/$Y$8 -> 1.4982535 | P15: {=_xlfn.IFS(AND(F15>15,F15<=30), "Youngsters", AND(F15>30,F15<=50), "Adults", AND(F15>50,F15<=70),"Old person", AND(F15>70, F15<92), "Senior Citizens")} -> Adults | Q15: {=_xlfn.IFS(G15=0,"No Tenure Period",AND(G15>0,G15<=3),"Less Tenure Period",AND(G15>3,G15<=7),"More Tenure Period",AND(G15>7,G15<=10),"Large Tenure Period")} -> Less Tenure Period | R15: {=_xlfn.IFS(AND(C15>300,C15<=525),"1 Star",AND(C15>525,C15<=600),"2 Star",AND(C15>600,C15<=700),"3 Star",AND(C15>700,C15<=750),"4 Star",AND(C15>750,C15<=900),"5 Star")} -> 3 Star | S15: {=_xlfn.IFS(E15="Male",1,E15="Female",2)} -> 1 | T15: {=_xlfn.IFS(D15="France",1,D15="Germany",2,D15="Spain",3)} -> 2
A16: 15 | B16: Johnson | C16: 684 | D16: Germany | E16: Male | F16: 89 | G16: 2 | H16: 60006.91 | I16: 2 | J16: 1 | K16: 0 | L16: 38571.28 | M16: 0 | N16: =(H16-$X$4)/$X$7 -> -0.95011228 | O16: =(L16-$Y$5)/$Y$8 -> -1.0666226 | P16: {=_xlfn.IFS(AND(F16>15,F16<=30), "Youngsters", AND(F16>30,F16<=50), "Adults", AND(F16>50,F16<=70),"Old person", AND(F16>70, F16<92), "Senior Citizens")} -> Senior Citizens | Q16: {=_xlfn.IFS(G16=0,"No Tenure Period",AND(G16>0,G16<=3),"Less Tenure Period",AND(G16>3,G16<=7),"More Tenure Period",AND(G16>7,G16<=10),"Large Tenure Period")} -> Less Tenure Period | R16: {=_xlfn.IFS(AND(C16>300,C16<=525),"1 Star",AND(C16>525,C16<=600),"2 Star",AND(C16>600,C16<=700),"3 Star",AND(C16>700,C16<=750),"4 Star",AND(C16>750,C16<=900),"5 Star")} -> 3 Star | S16: {=_xlfn.IFS(E16="Male",1,E16="Female",2)} -> 1 | T16: {=_xlfn.IFS(D16="France",1,D16="Germany",2,D16="Spain",3)} -> 2 | W16: Mean | X16: 0.54509018
A17: 16 | B17: Miller | C17: 579 | D17: France | E17: Female | F17: 42 | G17: 3 | H17: 180430.72 | I17: 4 | J17: 0 | K17: 1 | L17: 43961.45 | M17: 1 | N17: =(H17-$X$4)/$X$7 -> 0.7230797 | O17: =(L17-$Y$5)/$Y$8 -> -0.93490652 | P17: {=_xlfn.IFS(AND(F17>15,F17<=30), "Youngsters", AND(F17>30,F17<=50), "Adults", AND(F17>50,F17<=70),"Old person", AND(F17>70, F17<92), "Senior Citizens")} -> Adults | Q17: {=_xlfn.IFS(G17=0,"No Tenure Period",AND(G17>0,G17<=3),"Less Tenure Period",AND(G17>3,G17<=7),"More Tenure Period",AND(G17>7,G17<=10),"Large Tenure Period")} -> Less Tenure Period | R17: {=_xlfn.IFS(AND(C17>300,C17<=525),"1 Star",AND(C17>525,C17<=600),"2 Star",AND(C17>600,C17<=700),"3 Star",AND(C17>700,C17<=750),"4 Star",AND(C17>750,C17<=900),"5 Star")} -> 2 Star | S17: {=_xlfn.IFS(E17="Male",1,E17="Female",2)} -> 2 | T17: {=_xlfn.IFS(D17="France",1,D17="Germany",2,D17="Spain",3)} -> 1 | W17: Standard Error | X17: 0.022314243
A18: 17 | B18: Wilson | C18: 569 | D18: Germany | E18: Male | F18: 29 | G18: 7 | H18: 75466.39 | I18: 1 | J18: 0 | K18: 0 | L18: 103226.64 | M18: 1 | N18: =(H18-$X$4)/$X$7 -> -0.73531524 | O18: =(L18-$Y$5)/$Y$8 -> 0.51331789 | P18: {=_xlfn.IFS(AND(F18>15,F18<=30), "Youngsters", AND(F18>30,F18<=50), "Adults", AND(F18>50,F18<=70),"Old person", AND(F18>70, F18<92), "Senior Citizens")} -> Youngsters | Q18: {=_xlfn.IFS(G18=0,"No Tenure Period",AND(G18>0,G18<=3),"Less Tenure Period",AND(G18>3,G18<=7),"More Tenure Period",AND(G18>7,G18<=10),"Large Tenure Period")} -> More Tenure Period | R18: {=_xlfn.IFS(AND(C18>300,C18<=525),"1 Star",AND(C18>525,C18<=600),"2 Star",AND(C18>600,C18<=700),"3 Star",AND(C18>700,C18<=750),"4 Star",AND(C18>750,C18<=900),"5 Star")} -> 2 Star | S18: {=_xlfn.IFS(E18="Male",1,E18="Female",2)} -> 1 | T18: {=_xlfn.IFS(D18="France",1,D18="Germany",2,D18="Spain",3)} -> 2 | W18: Median | X18: 1
A19: 18 | B19: Wilson | C19: 596 | D19: Spain | E19: Male | F19: 40 | G19: 7 | H19: 124186.11 | I19: 3 | J19: 1 | K19: 1 | L19: 108305.55 | M19: 0 | N19: =(H19-$X$4)/$X$7 -> -0.058393914 | O19: =(L19-$Y$5)/$Y$8 -> 0.63742786 | P19: {=_xlfn.IFS(AND(F19>15,F19<=30), "Youngsters", AND(F19>30,F19<=50), "Adults", AND(F19>50,F19<=70),"Old person", AND(F19>70, F19<92), "Senior Citizens")} -> Adults | Q19: {=_xlfn.IFS(G19=0,"No Tenure Period",AND(G19>0,G19<=3),"Less Tenure Period",AND(G19>3,G19<=7),"More Tenure Period",AND(G19>7,G19<=10),"Large Tenure Period")} -> More Tenure Period | R19: {=_xlfn.IFS(AND(C19>300,C19<=525),"1 Star",AND(C19>525,C19<=600),"2 Star",AND(C19>600,C19<=700),"3 Star",AND(C19>700,C19<=750),"4 Star",AND(C19>750,C19<=900),"5 Star")} -> 2 Star | S19: {=_xlfn.IFS(E19="Male",1,E19="Female",2)} -> 1 | T19: {=_xlfn.IFS(D19="France",1,D19="Germany",2,D19="Spain",3)} -> 3 | W19: Mode | X19: 1
A20: 19 | B20: Moore | C20: 450 | D20: Germany | E20: Female | F20: 78 | G20: 1 | H20: 224549.07 | I20: 4 | J20: 0 | K20: 1 | L20: 144262.57 | M20: 1 | N20: =(H20-$X$4)/$X$7 -> 1.3360687 | O20: =(L20-$Y$5)/$Y$8 -> 1.5160859 | P20: {=_xlfn.IFS(AND(F20>15,F20<=30), "Youngsters", AND(F20>30,F20<=50), "Adults", AND(F20>50,F20<=70),"Old person", AND(F20>70, F20<92), "Senior Citizens")} -> Senior Citizens | Q20: {=_xlfn.IFS(G20=0,"No Tenure Period",AND(G20>0,G20<=3),"Less Tenure Period",AND(G20>3,G20<=7),"More Tenure Period",AND(G20>7,G20<=10),"Large Tenure Period")} -> Less Tenure Period | R20: {=_xlfn.IFS(AND(C20>300,C20<=525),"1 Star",AND(C20>525,C20<=600),"2 Star",AND(C20>600,C20<=700),"3 Star",AND(C20>700,C20<=750),"4 Star",AND(C20>750,C20<=900),"5 Star")} -> 1 Star | S20: {=_xlfn.IFS(E20="Male",1,E20="Female",2)} -> 2 | T20: {=_xlfn.IFS(D20="France",1,D20="Germany",2,D20="Spain",3)} -> 2 | W20: Standard Deviation | X20: 0.49846244
A21: 20 | B21: Johnson | C21: 765 | D21: Germany | E21: Female | F21: 20 | G21: 4 | H21: 246840.35 | I21: 2 | J21: 0 | K21: 0 | L21: 93337.31 | M21: 0 | N21: =(H21-$X$4)/$X$7 -> 1.6457881 | O21: =(L21-$Y$5)/$Y$8 -> 0.27165884 | P21: {=_xlfn.IFS(AND(F21>15,F21<=30), "Youngsters", AND(F21>30,F21<=50), "Adults", AND(F21>50,F21<=70),"Old person", AND(F21>70, F21<92), "Senior Citizens")} -> Youngsters | Q21: {=_xlfn.IFS(G21=0,"No Tenure Period",AND(G21>0,G21<=3),"Less Tenure Period",AND(G21>3,G21<=7),"More Tenure Period",AND(G21>7,G21<=10),"Large Tenure Period")} -> More Tenure Period | R21: {=_xlfn.IFS(AND(C21>300,C21<=525),"1 Star",AND(C21>525,C21<=600),"2 Star",AND(C21>600,C21<=700),"3 Star",AND(C21>700,C21<=750),"4 Star",AND(C21>750,C21<=900),"5 Star")} -> 5 Star | S21: {=_xlfn.IFS(E21="Male",1,E21="Female",2)} -> 2 | T21: {=_xlfn.IFS(D21="France",1,D21="Germany",2,D21="Spain",3)} -> 2 | W21: Sample Variance | X21: 0.2484648
A22: 21 | B22: Davis | C22: 571 | D22: France | E22: Male | F22: 26 | G22: 6 | H22: 239474.66 | I22: 1 | J22: 0 | K22: 1 | L22: 71646.19 | M22: 1 | N22: =(H22-$X$4)/$X$7 -> 1.5434478 | O22: =(L22-$Y$5)/$Y$8 -> -0.25839277 | P22: {=_xlfn.IFS(AND(F22>15,F22<=30), "Youngsters", AND(F22>30,F22<=50), "Adults", AND(F22>50,F22<=70),"Old person", AND(F22>70, F22<92), "Senior Citizens")} -> Youngsters | Q22: {=_xlfn.IFS(G22=0,"No Tenure Period",AND(G22>0,G22<=3),"Less Tenure Period",AND(G22>3,G22<=7),"More Tenure Period",AND(G22>7,G22<=10),"Large Tenure Period")} -> More Tenure Period | R22: {=_xlfn.IFS(AND(C22>300,C22<=525),"1 Star",AND(C22>525,C22<=600),"2 Star",AND(C22>600,C22<=700),"3 Star",AND(C22>700,C22<=750),"4 Star",AND(C22>750,C22<=900),"5 Star")} -> 2 Star | S22: {=_xlfn.IFS(E22="Male",1,E22="Female",2)} -> 1 | T22: {=_xlfn.IFS(D22="France",1,D22="Germany",2,D22="Spain",3)} -> 1 | W22: Kurtosis | X22: -1.9749368
A23: 22 | B23: Taylor | C23: 528 | D23: Spain | E23: Female | F23: 90 | G23: 10 | H23: 192616.6 | I23: 4 | J23: 1 | K23: 0 | L23: 27413.39 | M23: 0 | N23: =(H23-$X$4)/$X$7 -> 0.89239271 | O23: =(L23-$Y$5)/$Y$8 -> -1.3392806 | P23: {=_xlfn.IFS(AND(F23>15,F23<=30), "Youngsters", AND(F23>30,F23<=50), "Adults", AND(F23>50,F23<=70),"Old person", AND(F23>70, F23<92), "Senior Citizens")} -> Senior Citizens | Q23: {=_xlfn.IFS(G23=0,"No Tenure Period",AND(G23>0,G23<=3),"Less Tenure Period",AND(G23>3,G23<=7),"More Tenure Period",AND(G23>7,G23<=10),"Large Tenure Period")} -> Large Tenure Period | R23: {=_xlfn.IFS(AND(C23>300,C23<=525),"1 Star",AND(C23>525,C23<=600),"2 Star",AND(C23>600,C23<=700),"3 Star",AND(C23>700,C23<=750),"4 Star",AND(C23>750,C23<=900),"5 Star")} -> 2 Star | S23: {=_xlfn.IFS(E23="Male",1,E23="Female",2)} -> 2 | T23: {=_xlfn.IFS(D23="France",1,D23="Germany",2,D23="Spain",3)} -> 3 | W23: Skewness | X23: -0.1816451
A24: 23 | B24: Moore | C24: 524 | D24: Spain | E24: Male | F24: 56 | G24: 7 | H24: 34050.82 | I24: 4 | J24: 0 | K24: 1 | L24: 130037.45 | M24: 1 | N24: =(H24-$X$4)/$X$7 -> -1.3107513 | O24: =(L24-$Y$5)/$Y$8 -> 1.168476 | P24: {=_xlfn.IFS(AND(F24>15,F24<=30), "Youngsters", AND(F24>30,F24<=50), "Adults", AND(F24>50,F24<=70),"Old person", AND(F24>70, F24<92), "Senior Citizens")} -> Old person | Q24: {=_xlfn.IFS(G24=0,"No Tenure Period",AND(G24>0,G24<=3),"Less Tenure Period",AND(G24>3,G24<=7),"More Tenure Period",AND(G24>7,G24<=10),"Large Tenure Period")} -> More Tenure Period | R24: {=_xlfn.IFS(AND(C24>300,C24<=525),"1 Star",AND(C24>525,C24<=600),"2 Star",AND(C24>600,C24<=700),"3 Star",AND(C24>700,C24<=750),"4 Star",AND(C24>750,C24<=900),"5 Star")} -> 1 Star | S24: {=_xlfn.IFS(E24="Male",1,E24="Female",2)} -> 1 | T24: {=_xlfn.IFS(D24="France",1,D24="Germany",2,D24="Spain",3)} -> 3 | W24: Range | X24: 1
A25: 24 | B25: Taylor | C25: 443 | D25: France | E25: Female | F25: 70 | G25: 0 | H25: 116986.77 | I25: 2 | J25: 0 | K25: 0 | L25: 16197.08 | M25: 0 | N25: =(H25-$X$4)/$X$7 -> -0.15842295 | O25: =(L25-$Y$5)/$Y$8 -> -1.6133661 | P25: {=_xlfn.IFS(AND(F25>15,F25<=30), "Youngsters", AND(F25>30,F25<=50), "Adults", AND(F25>50,F25<=70),"Old person", AND(F25>70, F25<92), "Senior Citizens")} -> Old person | Q25: {=_xlfn.IFS(G25=0,"No Tenure Period",AND(G25>0,G25<=3),"Less Tenure Period",AND(G25>3,G25<=7),"More Tenure Period",AND(G25>7,G25<=10),"Large Tenure Period")} -> No Tenure Period | R25: {=_xlfn.IFS(AND(C25>300,C25<=525),"1 Star",AND(C25>525,C25<=600),"2 Star",AND(C25>600,C25<=700),"3 Star",AND(C25>700,C25<=750),"4 Star",AND(C25>750,C25<=900),"5 Star")} -> 1 Star | S25: {=_xlfn.IFS(E25="Male",1,E25="Female",2)} -> 2 | T25: {=_xlfn.IFS(D25="France",1,D25="Germany",2,D25="Spain",3)} -> 1 | W25: Minimum | X25: 0
A26: 25 | B26: Brown | C26: 464 | D26: Spain | E26: Female | F26: 81 | G26: 0 | H26: 242071.38 | I26: 2 | J26: 0 | K26: 0 | L26: 129312.08 | M26: 0 | N26: =(H26-$X$4)/$X$7 -> 1.5795271 | O26: =(L26-$Y$5)/$Y$8 -> 1.1507506 | P26: {=_xlfn.IFS(AND(F26>15,F26<=30), "Youngsters", AND(F26>30,F26<=50), "Adults", AND(F26>50,F26<=70),"Old person", AND(F26>70, F26<92), "Senior Citizens")} -> Senior Citizens | Q26: {=_xlfn.IFS(G26=0,"No Tenure Period",AND(G26>0,G26<=3),"Less Tenure Period",AND(G26>3,G26<=7),"More Tenure Period",AND(G26>7,G26<=10),"Large Tenure Period")} -> No Tenure Period | R26: {=_xlfn.IFS(AND(C26>300,C26<=525),"1 Star",AND(C26>525,C26<=600),"2 Star",AND(C26>600,C26<=700),"3 Star",AND(C26>700,C26<=750),"4 Star",AND(C26>750,C26<=900),"5 Star")} -> 1 Star | S26: {=_xlfn.IFS(E26="Male",1,E26="Female",2)} -> 2 | T26: {=_xlfn.IFS(D26="France",1,D26="Germany",2,D26="Spain",3)} -> 3 | W26: Maximum | X26: 1
A27: 26 | B27: Jones | C27: 511 | D27: Spain | E27: Female | F27: 39 | G27: 6 | H27: 88252.4 | I27: 2 | J27: 1 | K27: 1 | L27: 57083.95 | M27: 0 | N27: =(H27-$X$4)/$X$7 -> -0.55766391 | O27: =(L27-$Y$5)/$Y$8 -> -0.61424064 | P27: {=_xlfn.IFS(AND(F27>15,F27<=30), "Youngsters", AND(F27>30,F27<=50), "Adults", AND(F27>50,F27<=70),"Old person", AND(F27>70, F27<92), "Senior Citizens")} -> Adults | Q27: {=_xlfn.IFS(G27=0,"No Tenure Period",AND(G27>0,G27<=3),"Less Tenure Period",AND(G27>3,G27<=7),"More Tenure Period",AND(G27>7,G27<=10),"Large Tenure Period")} -> More Tenure Period | R27: {=_xlfn.IFS(AND(C27>300,C27<=525),"1 Star",AND(C27>525,C27<=600),"2 Star",AND(C27>600,C27<=700),"3 Star",AND(C27>700,C27<=750),"4 Star",AND(C27>750,C27<=900),"5 Star")} -> 1 Star | S27: {=_xlfn.IFS(E27="Male",1,E27="Female",2)} -> 2 | T27: {=_xlfn.IFS(D27="France",1,D27="Germany",2,D27="Spain",3)} -> 3 | W27: Sum | X27: 272
A28: 27 | B28: Smith | C28: 618 | D28: Germany | E28: Male | F28: 22 | G28: 4 | H28: 39874.14 | I28: 3 | J28: 1 | K28: 1 | L28: 137124.11 | M28: 1 | N28: =(H28-$X$4)/$X$7 -> -1.2298409 | O28: =(L28-$Y$5)/$Y$8 -> 1.341648 | P28: {=_xlfn.IFS(AND(F28>15,F28<=30), "Youngsters", AND(F28>30,F28<=50), "Adults", AND(F28>50,F28<=70),"Old person", AND(F28>70, F28<92), "Senior Citizens")} -> Youngsters | Q28: {=_xlfn.IFS(G28=0,"No Tenure Period",AND(G28>0,G28<=3),"Less Tenure Period",AND(G28>3,G28<=7),"More Tenure Period",AND(G28>7,G28<=10),"Large Tenure Period")} -> More Tenure Period | R28: {=_xlfn.IFS(AND(C28>300,C28<=525),"1 Star",AND(C28>525,C28<=600),"2 Star",AND(C28>600,C28<=700),"3 Star",AND(C28>700,C28<=750),"4 Star",AND(C28>750,C28<=900),"5 Star")} -> 3 Star | S28: {=_xlfn.IFS(E28="Male",1,E28="Female",2)} -> 1 | T28: {=_xlfn.IFS(D28="France",1,D28="Germany",2,D28="Spain",3)} -> 2 | W28: Count | X28: 499
A29: 28 | B29: Jones | C29: 574 | D29: France | E29: Male | F29: 49 | G29: 4 | H29: 47828.14 | I29: 3 | J29: 1 | K29: 0 | L29: 129087.2 | M29: 0 | N29: =(H29-$X$4)/$X$7 -> -1.1193265 | O29: =(L29-$Y$5)/$Y$8 -> 1.1452554 | P29: {=_xlfn.IFS(AND(F29>15,F29<=30), "Youngsters", AND(F29>30,F29<=50), "Adults", AND(F29>50,F29<=70),"Old person", AND(F29>70, F29<92), "Senior Citizens")} -> Adults | Q29: {=_xlfn.IFS(G29=0,"No Tenure Period",AND(G29>0,G29<=3),"Less Tenure Period",AND(G29>3,G29<=7),"More Tenure Period",AND(G29>7,G29<=10),"Large Tenure Period")} -> More Tenure Period | R29: {=_xlfn.IFS(AND(C29>300,C29<=525),"1 Star",AND(C29>525,C29<=600),"2 Star",AND(C29>600,C29<=700),"3 Star",AND(C29>700,C29<=750),"4 Star",AND(C29>750,C29<=900),"5 Star")} -> 2 Star | S29: {=_xlfn.IFS(E29="Male",1,E29="Female",2)} -> 1 | T29: {=_xlfn.IFS(D29="France",1,D29="Germany",2,D29="Spain",3)} -> 1
A30: 29 | B30: Davis | C30: 583 | D30: Spain | E30: Male | F30: 55 | G30: 10 | H30: 137337.08 | I30: 2 | J30: 0 | K30: 1 | L30: 107849.47 | M30: 1 | N30: =(H30-$X$4)/$X$7 -> 0.12432824 | O30: =(L30-$Y$5)/$Y$8 -> 0.62628294 | P30: {=_xlfn.IFS(AND(F30>15,F30<=30), "Youngsters", AND(F30>30,F30<=50), "Adults", AND(F30>50,F30<=70),"Old person", AND(F30>70, F30<92), "Senior Citizens")} -> Old person | Q30: {=_xlfn.IFS(G30=0,"No Tenure Period",AND(G30>0,G30<=3),"Less Tenure Period",AND(G30>3,G30<=7),"More Tenure Period",AND(G30>7,G30<=10),"Large Tenure Period")} -> Large Tenure Period | R30: {=_xlfn.IFS(AND(C30>300,C30<=525),"1 Star",AND(C30>525,C30<=600),"2 Star",AND(C30>600,C30<=700),"3 Star",AND(C30>700,C30<=750),"4 Star",AND(C30>750,C30<=900),"5 Star")} -> 2 Star | S30: {=_xlfn.IFS(E30="Male",1,E30="Female",2)} -> 1 | T30: {=_xlfn.IFS(D30="France",1,D30="Germany",2,D30="Spain",3)} -> 3
A31: 30 | B31: Smith | C31: 686 | D31: France | E31: Female | F31: 25 | G31: 5 | H31: 5425.45 | I31: 4 | J31: 1 | K31: 0 | L31: 82220.31 | M31: 1 | N31: =(H31-$X$4)/$X$7 -> -1.7084778 | O31: =(L31-$Y$5)/$Y$8 -> 3.6238263e-08 | P31: {=_xlfn.IFS(AND(F31>15,F31<=30), "Youngsters", AND(F31>30,F31<=50), "Adults", AND(F31>50,F31<=70),"Old person", AND(F31>70, F31<92), "Senior Citizens")} -> Youngsters | Q31: {=_xlfn.IFS(G31=0,"No Tenure Period",AND(G31>0,G31<=3),"Less Tenure Period",AND(G31>3,G31<=7),"More Tenure Period",AND(G31>7,G31<=10),"Large Tenure Period")} -> More Tenure Period | R31: {=_xlfn.IFS(AND(C31>300,C31<=525),"1 Star",AND(C31>525,C31<=600),"2 Star",AND(C31>600,C31<=700),"3 Star",AND(C31>700,C31<=750),"4 Star",AND(C31>750,C31<=900),"5 Star")} -> 3 Star | S31: {=_xlfn.IFS(E31="Male",1,E31="Female",2)} -> 2 | T31: {=_xlfn.IFS(D31="France",1,D31="Germany",2,D31="Spain",3)} -> 1
A32: 31 | B32: Williams | C32: 416 | D32: Germany | E32: Male | F32: 40 | G32: 1 | H32: 192565.36 | I32: 3 | J32: 0 | K32: 0 | L32: 106833.18 | M32: 1 | N32: =(H32-$X$4)/$X$7 -> 0.89168077 | O32: =(L32-$Y$5)/$Y$8 -> 0.60144853 | P32: {=_xlfn.IFS(AND(F32>15,F32<=30), "Youngsters", AND(F32>30,F32<=50), "Adults", AND(F32>50,F32<=70),"Old person", AND(F32>70, F32<92), "Senior Citizens")} -> Adults | Q32: {=_xlfn.IFS(G32=0,"No Tenure Period",AND(G32>0,G32<=3),"Less Tenure Period",AND(G32>3,G32<=7),"More Tenure Period",AND(G32>7,G32<=10),"Large Tenure Period")} -> Less Tenure Period | R32: {=_xlfn.IFS(AND(C32>300,C32<=525),"1 Star",AND(C32>525,C32<=600),"2 Star",AND(C32>600,C32<=700),"3 Star",AND(C32>700,C32<=750),"4 Star",AND(C32>750,C32<=900),"5 Star")} -> 1 Star | S32: {=_xlfn.IFS(E32="Male",1,E32="Female",2)} -> 1 | T32: {=_xlfn.IFS(D32="France",1,D32="Germany",2,D32="Spain",3)} -> 2
A33: 32 | B33: Jones | C33: 806 | D33: Spain | E33: Female | F33: 60 | G33: 10 | H33: 98142.26 | I33: 4 | J33: 0 | K33: 1 | L33: 88655.49 | M33: 1 | N33: =(H33-$X$4)/$X$7 -> -0.42025226 | O33: =(L33-$Y$5)/$Y$8 -> 0.15725229 | P33: {=_xlfn.IFS(AND(F33>15,F33<=30), "Youngsters", AND(F33>30,F33<=50), "Adults", AND(F33>50,F33<=70),"Old person", AND(F33>70, F33<92), "Senior Citizens")} -> Old person | Q33: {=_xlfn.IFS(G33=0,"No Tenure Period",AND(G33>0,G33<=3),"Less Tenure Period",AND(G33>3,G33<=7),"More Tenure Period",AND(G33>7,G33<=10),"Large Tenure Period")} -> Large Tenure Period | R33: {=_xlfn.IFS(AND(C33>300,C33<=525),"1 Star",AND(C33>525,C33<=600),"2 Star",AND(C33>600,C33<=700),"3 Star",AND(C33>700,C33<=750),"4 Star",AND(C33>750,C33<=900),"5 Star")} -> 5 Star | S33: {=_xlfn.IFS(E33="Male",1,E33="Female",2)} -> 2 | T33: {=_xlfn.IFS(D33="France",1,D33="Germany",2,D33="Spain",3)} -> 3
A34: 33 | B34: Moore | C34: 849 | D34: France | E34: Female | F34: 77 | G34: 2 | H34: 55839.55 | I34: 1 | J34: 1 | K34: 1 | L34: 45305.66 | M34: 1 | N34: =(H34-$X$4)/$X$7 -> -1.0080144 | O34: =(L34-$Y$5)/$Y$8 -> -0.90205895 | P34: {=_xlfn.IFS(AND(F34>15,F34<=30), "Youngsters", AND(F34>30,F34<=50), "Adults", AND(F34>50,F34<=70),"Old person", AND(F34>70, F34<92), "Senior Citizens")} -> Senior Citizens | Q34: {=_xlfn.IFS(G34=0,"No Tenure Period",AND(G34>0,G34<=3),"Less Tenure Period",AND(G34>3,G34<=7),"More Tenure Period",AND(G34>7,G34<=10),"Large Tenure Period")} -> Less Tenure Period | R34: {=_xlfn.IFS(AND(C34>300,C34<=525),"1 Star",AND(C34>525,C34<=600),"2 Star",AND(C34>600,C34<=700),"3 Star",AND(C34>700,C34<=750),"4 Star",AND(C34>750,C34<=900),"5 Star")} -> 5 Star | S34: {=_xlfn.IFS(E34="Male",1,E34="Female",2)} -> 2 | T34: {=_xlfn.IFS(D34="France",1,D34="Germany",2,D34="Spain",3)} -> 1
A35: 34 | B35: Johnson | C35: 475 | D35: Spain | E35: Male | F35: 72 | G35: 6 | H35: 72899.17 | I35: 1 | J35: 0 | K35: 0 | L35: 90761.77 | M35: 0 | N35: =(H35-$X$4)/$X$7 -> -0.7709847 | O35: =(L35-$Y$5)/$Y$8 -> 0.20872207 | P35: {=_xlfn.IFS(AND(F35>15,F35<=30), "Youngsters", AND(F35>30,F35<=50), "Adults", AND(F35>50,F35<=70),"Old person", AND(F35>70, F35<92), "Senior Citizens")} -> Senior Citizens | Q35: {=_xlfn.IFS(G35=0,"No Tenure Period",AND(G35>0,G35<=3),"Less Tenure Period",AND(G35>3,G35<=7),"More Tenure Period",AND(G35>7,G35<=10),"Large Tenure Period")} -> More Tenure Period | R35: {=_xlfn.IFS(AND(C35>300,C35<=525),"1 Star",AND(C35>525,C35<=600),"2 Star",AND(C35>600,C35<=700),"3 Star",AND(C35>700,C35<=750),"4 Star",AND(C35>750,C35<=900),"5 Star")} -> 1 Star | S35: {=_xlfn.IFS(E35="Male",1,E35="Female",2)} -> 1 | T35: {=_xlfn.IFS(D35="France",1,D35="Germany",2,D35="Spain",3)} -> 3
A36: 35 | B36: Jones | C36: 488 | D36: France | E36: Female | F36: 91 | G36: 8 | H36: 200786.02 | I36: 1 | J36: 0 | K36: 0 | L36: 128936.13 | M36: 1 | N36: =(H36-$X$4)/$X$7 -> 1.0059002 | O36: =(L36-$Y$5)/$Y$8 -> 1.1415638 | P36: {=_xlfn.IFS(AND(F36>15,F36<=30), "Youngsters", AND(F36>30,F36<=50), "Adults", AND(F36>50,F36<=70),"Old person", AND(F36>70, F36<92), "Senior Citizens")} -> Senior Citizens | Q36: {=_xlfn.IFS(G36=0,"No Tenure Period",AND(G36>0,G36<=3),"Less Tenure Period",AND(G36>3,G36<=7),"More Tenure Period",AND(G36>7,G36<=10),"Large Tenure Period")} -> Large Tenure Period | R36: {=_xlfn.IFS(AND(C36>300,C36<=525),"1 Star",AND(C36>525,C36<=600),"2 Star",AND(C36>600,C36<=700),"3 Star",AND(C36>700,C36<=750),"4 Star",AND(C36>750,C36<=900),"5 Star")} -> 1 Star | S36: {=_xlfn.IFS(E36="Male",1,E36="Female",2)} -> 2 | T36: {=_xlfn.IFS(D36="France",1,D36="Germany",2,D36="Spain",3)} -> 1
A37: 36 | B37: Jones | C37: 462 | D37: Germany | E37: Male | F37: 69 | G37: 2 | H37: 9295.29 | I37: 3 | J37: 0 | K37: 0 | L37: 39491.23 | M37: 1 | N37: =(H37-$X$4)/$X$7 -> -1.6547095 | O37: =(L37-$Y$5)/$Y$8 -> -1.0441423 | P37: {=_xlfn.IFS(AND(F37>15,F37<=30), "Youngsters", AND(F37>30,F37<=50), "Adults", AND(F37>50,F37<=70),"Old person", AND(F37>70, F37<92), "Senior Citizens")} -> Old person | Q37: {=_xlfn.IFS(G37=0,"No Tenure Period",AND(G37>0,G37<=3),"Less Tenure Period",AND(G37>3,G37<=7),"More Tenure Period",AND(G37>7,G37<=10),"Large Tenure Period")} -> Less Tenure Period | R37: {=_xlfn.IFS(AND(C37>300,C37<=525),"1 Star",AND(C37>525,C37<=600),"2 Star",AND(C37>600,C37<=700),"3 Star",AND(C37>700,C37<=750),"4 Star",AND(C37>750,C37<=900),"5 Star")} -> 1 Star | S37: {=_xlfn.IFS(E37="Male",1,E37="Female",2)} -> 1 | T37: {=_xlfn.IFS(D37="France",1,D37="Germany",2,D37="Spain",3)} -> 2
A38: 37 | B38: Jones | C38: 568 | D38: Germany | E38: Female | F38: 41 | G38: 10 | H38: 192830.21 | I38: 2 | J38: 0 | K38: 0 | L38: 82220.31 | M38: 0 | N38: =(H38-$X$4)/$X$7 -> 0.89536065 | O38: =(L38-$Y$5)/$Y$8 -> 3.6238263e-08 | P38: {=_xlfn.IFS(AND(F38>15,F38<=30), "Youngsters", AND(F38>30,F38<=50), "Adults", AND(F38>50,F38<=70),"Old person", AND(F38>70, F38<92), "Senior Citizens")} -> Adults | Q38: {=_xlfn.IFS(G38=0,"No Tenure Period",AND(G38>0,G38<=3),"Less Tenure Period",AND(G38>3,G38<=7),"More Tenure Period",AND(G38>7,G38<=10),"Large Tenure Period")} -> Large Tenure Period | R38: {=_xlfn.IFS(AND(C38>300,C38<=525),"1 Star",AND(C38>525,C38<=600),"2 Star",AND(C38>600,C38<=700),"3 Star",AND(C38>700,C38<=750),"4 Star",AND(C38>750,C38<=900),"5 Star")} -> 2 Star | S38: {=_xlfn.IFS(E38="Male",1,E38="Female",2)} -> 2 | T38: {=_xlfn.IFS(D38="France",1,D38="Germany",2,D38="Spain",3)} -> 2
A39: 38 | B39: Wilson | C39: 505 | D39: Spain | E39: Male | F39: 43 | G39: 9 | H39: 190574.23 | I39: 1 | J39: 1 | K39: 0 | L39: 22363.52 | M39: 0 | N39: =(H39-$X$4)/$X$7 -> 0.86401562 | O39: =(L39-$Y$5)/$Y$8 -> -1.4626809 | P39: {=_xlfn.IFS(AND(F39>15,F39<=30), "Youngsters", AND(F39>30,F39<=50), "Adults", AND(F39>50,F39<=70),"Old person", AND(F39>70, F39<92), "Senior Citizens")} -> Adults | Q39: {=_xlfn.IFS(G39=0,"No Tenure Period",AND(G39>0,G39<=3),"Less Tenure Period",AND(G39>3,G39<=7),"More Tenure Period",AND(G39>7,G39<=10),"Large Tenure Period")} -> Large Tenure Period | R39: {=_xlfn.IFS(AND(C39>300,C39<=525),"1 Star",AND(C39>525,C39<=600),"2 Star",AND(C39>600,C39<=700),"3 Star",AND(C39>700,C39<=750),"4 Star",AND(C39>750,C39<=900),"5 Star")} -> 1 Star | S39: {=_xlfn.IFS(E39="Male",1,E39="Female",2)} -> 1 | T39: {=_xlfn.IFS(D39="France",1,D39="Germany",2,D39="Spain",3)} -> 3
A40: 39 | B40: Smith | C40: 534 | D40: Spain | E40: Female | F40: 75 | G40: 9 | H40: 20385.3 | I40: 1 | J40: 0 | K40: 0 | L40: 118972.35 | M40: 1 | N40: =(H40-$X$4)/$X$7 -> -1.5006227 | O40: =(L40-$Y$5)/$Y$8 -> 0.89808543 | P40: {=_xlfn.IFS(AND(F40>15,F40<=30), "Youngsters", AND(F40>30,F40<=50), "Adults", AND(F40>50,F40<=70),"Old person", AND(F40>70, F40<92), "Senior Citizens")} -> Senior Citizens | Q40: {=_xlfn.IFS(G40=0,"No Tenure Period",AND(G40>0,G40<=3),"Less Tenure Period",AND(G40>3,G40<=7),"More Tenure Period",AND(G40>7,G40<=10),"Large Tenure Period")} -> Large Tenure Period | R40: {=_xlfn.IFS(AND(C40>300,C40<=525),"1 Star",AND(C40>525,C40<=600),"2 Star",AND(C40>600,C40<=700),"3 Star",AND(C40>700,C40<=750),"4 Star",AND(C40>750,C40<=900),"5 Star")} -> 2 Star | S40: {=_xlfn.IFS(E40="Male",1,E40="Female",2)} -> 2 | T40: {=_xlfn.IFS(D40="France",1,D40="Germany",2,D40="Spain",3)} -> 3
...

Sheet Age vs CS
A1: Age Category | B1: =DATA!R1 -> CS Category | D1: Row Labels | E1: Count of CS Category | G1: Age | H1: =DATA!C1 -> CreditScore | K1: Age | L1: CreditScore
A2: Youngsters | B2: =DATA!R2 -> 5 Star | D2: Adults | E2: 136 | G2: 20 | H2: =DATA!C2 -> 764 | J2: Age | K2: 1
A3: Old person | B3: =DATA!R3 -> 1 Star | D3: 1 Star | E3: 49 | G3: 64 | H3: =DATA!C3 -> 365 | J3: CreditScore | K3: -0.050991838 | L3: 1
A4: Old person | B4: =DATA!R4 -> 1 Star | D4: 2 Star | E4: 24 | G4: 69 | H4: =DATA!C4 -> 519
A5: Old person | B5: =DATA!R5 -> 1 Star | D5: 3 Star | E5: 22 | G5: 59 | H5: =DATA!C5 -> 516
A6: Youngsters | B6: =DATA!R6 -> 3 Star | D6: 4 Star | E6: 18 | G6: 21 | H6: =DATA!C6 -> 659 | J6: SUMMARY OUTPUT
A7: Adults | B7: =DATA!R7 -> 5 Star | D7: 5 Star | E7: 23 | G7: 34 | H7: =DATA!C7 -> 777
A8: Senior Citizens | B8: =DATA!R8 -> 1 Star | D8: Old person | E8: 125 | G8: 81 | H8: =DATA!C8 -> 432 | J8: Regression Statistics
A9: Senior Citizens | B9: =DATA!R9 -> 4 Star | D9: 1 Star | E9: 49 | G9: 82 | H9: =DATA!C9 -> 741 | J9: Multiple R | K9: 0.050991838
A10: Adults | B10: =DATA!R10 -> 2 Star | D10: 2 Star | E10: 20 | G10: 31 | H10: =DATA!C10 -> 570 | J10: R Square | K10: 0.0026001675
A11: Old person | B11: =DATA!R11 -> 3 Star | D11: 3 Star | E11: 26 | G11: 56 | H11: =DATA!C11 -> 671 | J11: Adjusted R Square | K11: 0.00059332681
A12: Youngsters | B12: =DATA!R12 -> 1 Star | D12: 4 Star | E12: 14 | G12: 22 | H12: =DATA!C12 -> 519 | J12: Standard Error | K12: 137.67999
A13: Youngsters | B13: =DATA!R13 -> 3 Star | D13: 5 Star | E13: 16 | G13: 21 | H13: =DATA!C13 -> 672 | J13: Observations | K13: 499
A14: Adults | B14: =DATA!R14 -> 1 Star | D14: Senior Citizens | E14: 144 | G14: 37 | H14: =DATA!C14 -> 464
A15: Adults | B15: =DATA!R15 -> 3 Star | D15: 1 Star | E15: 59 | G15: 34 | H15: =DATA!C15 -> 698 | J15: ANOVA
A16: Senior Citizens | B16: =DATA!R16 -> 3 Star | D16: 2 Star | E16: 21 | G16: 89 | H16: =DATA!C16 -> 684 | K16: df | L16: SS | M16: MS | N16: F | O16: Significance F
A17: Adults | B17: =DATA!R17 -> 2 Star | D17: 3 Star | E17: 26 | G17: 42 | H17: =DATA!C17 -> 579 | J17: Regression | K17: 1 | L17: 24560.098 | M17: 24560.098 | N17: 1.2956522 | O17: 0.25555733
A18: Youngsters | B18: =DATA!R18 -> 2 Star | D18: 4 Star | E18: 17 | G18: 29 | H18: =DATA!C18 -> 569 | J18: Residual | K18: 497 | L18: 9421022.8 | M18: 18955.78
A19: Adults | B19: =DATA!R19 -> 2 Star | D19: 5 Star | E19: 21 | G19: 40 | H19: =DATA!C19 -> 596 | J19: Total | K19: 498 | L19: 9445582.9
A20: Senior Citizens | B20: =DATA!R20 -> 1 Star | D20: Youngsters | E20: 94 | G20: 78 | H20: =DATA!C20 -> 450
A21: Youngsters | B21: =DATA!R21 -> 5 Star | D21: 1 Star | E21: 32 | G21: 20 | H21: =DATA!C21 -> 765 | K21: Coefficients | L21: Standard Error | M21: t Stat | N21: P-value | O21: Lower 95% | P21: Upper 95% | Q21: Lower 95.0% | R21: Upper 95.0%
A22: Youngsters | B22: =DATA!R22 -> 2 Star | D22: 2 Star | E22: 15 | G22: 26 | H22: =DATA!C22 -> 571 | J22: Intercept | K22: 609.1784 | L22: 16.546545 | M22: 36.816048 | N22: 4.288293e-144 | O22: 576.6686 | P22: 641.68821 | Q22: 576.6686 | R22: 641.68821
A23: Senior Citizens | B23: =DATA!R23 -> 2 Star | D23: 3 Star | E23: 22 | G23: 90 | H23: =DATA!C23 -> 528 | J23: Age | K23: -0.32301397 | L23: 0.28377693 | M23: -1.1382672 | N23: 0.25555733 | O23: -0.88056431 | P23: 0.23453637 | Q23: -0.88056431 | R23: 0.23453637
A24: Old person | B24: =DATA!R24 -> 1 Star | D24: 4 Star | E24: 9 | G24: 56 | H24: =DATA!C24 -> 524
A25: Old person | B25: =DATA!R25 -> 1 Star | D25: 5 Star | E25: 16 | G25: 70 | H25: =DATA!C25 -> 443
A26: Senior Citizens | B26: =DATA!R26 -> 1 Star | D26: Grand Total | E26: 499 | G26: 81 | H26: =DATA!C26 -> 464
A27: Adults | B27: =DATA!R27 -> 1 Star | G27: 39 | H27: =DATA!C27 -> 511
A28: Youngsters | B28: =DATA!R28 -> 3 Star | G28: 22 | H28: =DATA!C28 -> 618
A29: Adults | B29: =DATA!R29 -> 2 Star | G29: 49 | H29: =DATA!C29 -> 574
A30: Old person | B30: =DATA!R30 -> 2 Star | G30: 55 | H30: =DATA!C30 -> 583
A31: Youngsters | B31: =DATA!R31 -> 3 Star | G31: 25 | H31: =DATA!C31 -> 686
A32: Adults | B32: =DATA!R32 -> 1 Star | G32: 40 | H32: =DATA!C32 -> 416
A33: Old person | B33: =DATA!R33 -> 5 Star | G33: 60 | H33: =DATA!C33 -> 806
A34: Senior Citizens | B34: =DATA!R34 -> 5 Star | G34: 77 | H34: =DATA!C34 -> 849
A35: Senior Citizens | B35: =DATA!R35 -> 1 Star | G35: 72 | H35: =DATA!C35 -> 475
A36: Senior Citizens | B36: =DATA!R36 -> 1 Star | G36: 91 | H36: =DATA!C36 -> 488
A37: Old person | B37: =DATA!R37 -> 1 Star | G37: 69 | H37: =DATA!C37 -> 462
A38: Adults | B38: =DATA!R38 -> 2 Star | G38: 41 | H38: =DATA!C38 -> 568
... A500: Youngsters | B500: =DATA!R500 -> 1 Star | G500: 23 | H500: =DATA!C500 -> 393

Sheet Gender Geography Age
A3: Row Labels | B3: Count of Churn
A4: Female | B4: 258
A5: 0 | B5: 129
A6: 1 | B6: 129
B7: 241
A8: 0 | B8: 98
A9: 1 | B9: 143
A10: Grand Total | B10: 499
A13: Row Labels | B13: Count of Churn
A14: France | B14: 171
A15: 0 | B15: 69
A16: 1 | B16: 102
A17: Grand Total | B17: 171
A21: Row Labels | B21: Count of Churn
A22: Senior Citizens | B22: 144
A23: 0 | B23: 62
A24: 1 | B24: 82
A25: Grand Total | B25: 144

Sheet Active Cr.Card Products
A1: Is Active Member | B1: Count of Churn
A2: 0 | B2: 262
A3: 1 | B3: 237
A4: Grand Total | B4: 499
A11: Has Cr. Card | B11: Count of Churn
A12: 0 | B12: 252
A13: 0 | B13: 111
A14: 1 | B14: 141
A15: 1 | B15: 247
A16: 0 | B16: 116
A17: 1 | B17: 131
A18: Grand Total | B18: 499
A21: No. Of Products | B21: Count of Churn
A22: 1 | B22: 125
A23: 0 | B23: 56
A24: 1 | B24: 69
A25: 2 | B25: 134
A26: 0 | B26: 60
A27: 1 | B27: 74
A28: 3 | B28: 118
A29: 0 | B29: 53
A30: 1 | B30: 65
A31: 4 | B31: 122
A32: 0 | B32: 58
A33: 1 | B33: 64
A34: Grand Total | B34: 499

Sheet Tenure Cr. Score
A1: Tenure Period | B1: Count of Churn | D1: Count of Churn | E1: Column Labels
A2: Large Tenure Period | B2: 147 | D2: Tenure | E2: 0 | F2: 1 | G2: Grand Total
A3: 0 | B3: 64 | D3: 0 | E3: 26 | F3: 17 | G3: 43
A4: 1 | B4: 83 | D4: 1 | E4: 20 | F4: 24 | G4: 44
A5: Grand Total | B5: 147 | D5: 2 | E5: 22 | F5: 25 | G5: 47
D6: 3 | E6: 16 | F6: 24 | G6: 40
D7: 4 | E7: 23 | F7: 21 | G7: 44
D8: 5 | E8: 20 | F8: 24 | G8: 44
D9: 6 | E9: 19 | F9: 28 | G9: 47 | J9: k
D10: 7 | E10: 17 | F10: 26 | G10: 43
D11: 8 | E11: 15 | F11: 24 | G11: 39
D12: 9 | E12: 20 | F12: 33 | G12: 53
D13: 10 | E13: 29 | F13: 26 | G13: 55
D14: Grand Total | E14: 227 | F14: 272 | G14: 499
A19: Count of Churn | B19: Column Labels
A20: Row Labels | B20: 0 | C20: 1 | D20: Grand Total
A21: 1 Star | B21: 83 | C21: 106 | D21: 189
A22: 2 Star | B22: 36 | C22: 44 | D22: 80
A23: 3 Star | B23: 42 | C23: 54 | D23: 96
A24: 4 Star | B24: 30 | C24: 28 | D24: 58
A25: 5 Star | B25: 36 | C25: 40 | D25: 76
A26: Grand Total | B26: 227 | C26: 272 | D26: 499

Sheet RA
A1: {=DATA!S1:S500} -> Gender Category | B1: =DATA!T1 -> Geography Category | C1: =DATA!F1 -> Age | D1: =DATA!M1 -> Churn
A2: 1 | B2: =DATA!T2 -> 2 | C2: =DATA!F2 -> 20 | D2: =DATA!M2 -> 0 | G2: SUMMARY OUTPUT
A3: 2 | B3: =DATA!T3 -> 3 | C3: =DATA!F3 -> 64 | D3: =DATA!M3 -> 0
A4: 1 | B4: =DATA!T4 -> 2 | C4: =DATA!F4 -> 69 | D4: =DATA!M4 -> 0 | G4: Regression Statistics
A5: 2 | B5: =DATA!T5 -> 2 | C5: =DATA!F5 -> 59 | D5: =DATA!M5 -> 0 | G5: Multiple R | H5: 0.11719686
A6: 2 | B6: =DATA!T6 -> 3 | C6: =DATA!F6 -> 21 | D6: =DATA!M6 -> 0 | G6: R Square | H6: 0.013735104
A7: 2 | B7: =DATA!T7 -> 3 | C7: =DATA!F7 -> 34 | D7: =DATA!M7 -> 0 | G7: Adjusted R Square | H7: 0.0077577411
A8: 2 | B8: =DATA!T8 -> 2 | C8: =DATA!F8 -> 81 | D8: =DATA!M8 -> 0 | G8: Standard Error | H8: 0.4965252
A9: 1 | B9: =DATA!T9 -> 1 | C9: =DATA!F9 -> 82 | D9: =DATA!M9 -> 1 | G9: Observations | H9: 499
A10: 2 | B10: =DATA!T10 -> 2 | C10: =DATA!F10 -> 31 | D10: =DATA!M10 -> 1
A11: 2 | B11: =DATA!T11 -> 1 | C11: =DATA!F11 -> 56 | D11: =DATA!M11 -> 1 | G11: ANOVA
A12: 2 | B12: =DATA!T12 -> 1 | C12: =DATA!F12 -> 22 | D12: =DATA!M12 -> 1 | H12: df | I12: SS | J12: MS | K12: F | L12: Significance F
A13: 1 | B13: =DATA!T13 -> 2 | C13: =DATA!F13 -> 21 | D13: =DATA!M13 -> 1 | G13: Regression | H13: 3 | I13: 1.6995196 | J13: 0.56650652 | K13: 2.2978534 | L13: 0.076737061
A14: 2 | B14: =DATA!T14 -> 3 | C14: =DATA!F14 -> 37 | D14: =DATA!M14 -> 0 | G14: Residual | H14: 495 | I14: 122.03595 | J14: 0.24653728
A15: 1 | B15: =DATA!T15 -> 2 | C15: =DATA!F15 -> 34 | D15: =DATA!M15 -> 1 | G15: Total | H15: 498 | I15: 123.73547
A16: 1 | B16: =DATA!T16 -> 2 | C16: =DATA!F16 -> 89 | D16: =DATA!M16 -> 0
A17: 2 | B17: =DATA!T17 -> 1 | C17: =DATA!F17 -> 42 | D17: =DATA!M17 -> 1 | H17: Coefficients | I17: Standard Error | J17: t Stat | K17: P-value | L17: Lower 95% | M17: Upper 95% | N17: Lower 95.0% | O17: Upper 95.0%
A18: 1 | B18: =DATA!T18 -> 2 | C18: =DATA!F18 -> 29 | D18: =DATA!M18 -> 1 | G18: Intercept | H18: 0.77009891 | I18: 0.10675439 | J18: 7.2137447 | K18: 2.054714e-12 | L18: 0.56035131 | M18: 0.97984652 | N18: 0.56035131 | O18: 0.97984652
A19: 1 | B19: =DATA!T19 -> 3 | C19: =DATA!F19 -> 40 | D19: =DATA!M19 -> 0 | G19: Gender Category | H19: -0.094980832 | I19: 0.044509276 | J19: -2.1339559 | K19: 0.033337237 | L19: -0.18243123 | M19: -0.0075304308 | N19: -0.18243123 | O19: -0.0075304308
A20: 2 | B20: =DATA!T20 -> 2 | C20: =DATA!F20 -> 78 | D20: =DATA!M20 -> 1 | G20: Geography Category | H20: -0.042320461 | I20: 0.026856989 | J20: -1.5757709 | K20: 0.11571748 | L20: -0.095088212 | M20: 0.010447291 | N20: -0.095088212 | O20: 0.010447291
A21: 2 | B21: =DATA!T21 -> 2 | C21: =DATA!F21 -> 20 | D21: =DATA!M21 -> 0 | G21: Age | H21: 6.8770893e-05 | I21: 0.0010237607 | J21: 0.067174776 | K21: 0.94646969 | L21: -0.0019426813 | M21: 0.0020802231 | N21: -0.0019426813 | O21: 0.0020802231
A22: 1 | B22: =DATA!T22 -> 1 | C22: =DATA!F22 -> 26 | D22: =DATA!M22 -> 1
A23: 2 | B23: =DATA!T23 -> 3 | C23: =DATA!F23 -> 90 | D23: =DATA!M23 -> 0
A24: 1 | B24: =DATA!T24 -> 3 | C24: =DATA!F24 -> 56 | D24: =DATA!M24 -> 1
A25: 2 | B25: =DATA!T25 -> 1 | C25: =DATA!F25 -> 70 | D25: =DATA!M25 -> 0
A26: 2 | B26: =DATA!T26 -> 3 | C26: =DATA!F26 -> 81 | D26: =DATA!M26 -> 0
A27: 2 | B27: =DATA!T27 -> 3 | C27: =DATA!F27 -> 39 | D27: =DATA!M27 -> 0
A28: 1 | B28: =DATA!T28 -> 2 | C28: =DATA!F28 -> 22 | D28: =DATA!M28 -> 1
A29: 1 | B29: =DATA!T29 -> 1 | C29: =DATA!F29 -> 49 | D29: =DATA!M29 -> 0
A30: 1 | B30: =DATA!T30 -> 3 | C30: =DATA!F30 -> 55 | D30: =DATA!M30 -> 1
A31: 2 | B31: =DATA!T31 -> 1 | C31: =DATA!F31 -> 25 | D31: =DATA!M31 -> 1
A32: 1 | B32: =DATA!T32 -> 2 | C32: =DATA!F32 -> 40 | D32: =DATA!M32 -> 1
A33: 2 | B33: =DATA!T33 -> 3 | C33: =DATA!F33 -> 60 | D33: =DATA!M33 -> 1
... A500: 1 | B500: =DATA!T500 -> 2 | C500: =DATA!F500 -> 23 | D500: =DATA!M500 -> 1

Sheet RA2
A1: {=DATA!K1:K500} -> IsActiveMember | B1: =DATA!C1 -> CreditScore | C1: =DATA!I1 -> NumOfProducts | D1: =DATA!M1 -> Churn
A2: 0 | B2: =DATA!C2 -> 764 | C2: =DATA!I2 -> 3 | D2: =DATA!M2 -> 0
A3: 1 | B3: =DATA!C3 -> 365 | C3: =DATA!I3 -> 3 | D3: =DATA!M3 -> 0
A4: 0 | B4: =DATA!C4 -> 519 | C4: =DATA!I4 -> 3 | D4: =DATA!M4 -> 0 | G4: SUMMARY OUTPUT
A5: 0 | B5: =DATA!C5 -> 516 | C5: =DATA!I5 -> 1 | D5: =DATA!M5 -> 0
A6: 1 | B6: =DATA!C6 -> 659 | C6: =DATA!I6 -> 1 | D6: =DATA!M6 -> 0 | G6: Regression Statistics
A7: 0 | B7: =DATA!C7 -> 777 | C7: =DATA!I7 -> 4 | D7: =DATA!M7 -> 0 | G7: Multiple R | H7: 0.039039193
A8: 0 | B8: =DATA!C8 -> 432 | C8: =DATA!I8 -> 4 | D8: =DATA!M8 -> 0 | G8: R Square | H8: 0.0015240586
A9: 1 | B9: =DATA!C9 -> 741 | C9: =DATA!I9 -> 2 | D9: =DATA!M9 -> 1 | G9: Adjusted R Square | H9: -0.0045273108
A10: 1 | B10: =DATA!C10 -> 570 | C10: =DATA!I10 -> 2 | D10: =DATA!M10 -> 1 | G10: Standard Error | H10: 0.49958951
A11: 0 | B11: =DATA!C11 -> 671 | C11: =DATA!I11 -> 2 | D11: =DATA!M11 -> 1 | G11: Observations | H11: 499
A12: 0 | B12: =DATA!C12 -> 519 | C12: =DATA!I12 -> 3 | D12: =DATA!M12 -> 1
A13: 0 | B13: =DATA!C13 -> 672 | C13: =DATA!I13 -> 3 | D13: =DATA!M13 -> 1 | G13: ANOVA
A14: 0 | B14: =DATA!C14 -> 464 | C14: =DATA!I14 -> 3 | D14: =DATA!M14 -> 0 | H14: df | I14: SS | J14: MS | K14: F | L14: Significance F
A15: 0 | B15: =DATA!C15 -> 698 | C15: =DATA!I15 -> 1 | D15: =DATA!M15 -> 1 | G15: Regression | H15: 3 | I15: 0.18858011 | J15: 0.062860036 | K15: 0.25185351 | L15: 0.86001994
A16: 0 | B16: =DATA!C16 -> 684 | C16: =DATA!I16 -> 2 | D16: =DATA!M16 -> 0 | G16: Residual | H16: 495 | I16: 123.54689 | J16: 0.24958968
A17: 1 | B17: =DATA!C17 -> 579 | C17: =DATA!I17 -> 4 | D17: =DATA!M17 -> 1 | G17: Total | H17: 498 | I17: 123.73547
A18: 0 | B18: =DATA!C18 -> 569 | C18: =DATA!I18 -> 1 | D18: =DATA!M18 -> 1
A19: 1 | B19: =DATA!C19 -> 596 | C19: =DATA!I19 -> 3 | D19: =DATA!M19 -> 0 | H19: Coefficients | I19: Standard Error | J19: t Stat | K19: P-value | L19: Lower 95% | M19: Upper 95% | N19: Lower 95.0% | O19: Upper 95.0%
A20: 1 | B20: =DATA!C20 -> 450 | C20: =DATA!I20 -> 4 | D20: =DATA!M20 -> 1 | G20: Intercept | H20: 0.62702027 | I20: 0.11472872 | J20: 5.4652423 | K20: 7.3384299e-08 | L20: 0.40160495 | M20: 0.85243559 | N20: 0.40160495 | O20: 0.85243559
A21: 0 | B21: =DATA!C21 -> 765 | C21: =DATA!I21 -> 2 | D21: =DATA!M21 -> 0 | G21: IsActiveMember | H21: 0.012461559 | I21: 0.04487125 | J21: 0.27771811 | K21: 0.78134471 | L21: -0.075700037 | M21: 0.10062316 | N21: -0.075700037 | O21: 0.10062316
A22: 1 | B22: =DATA!C22 -> 571 | C22: =DATA!I22 -> 1 | D22: =DATA!M22 -> 1 | G22: CreditScore | H22: -0.00011270619 | I22: 0.00016287504 | J22: -0.6919795 | K22: 0.48927465 | L22: -0.00043271786 | M22: 0.00020730548 | N22: -0.00043271786 | O22: 0.00020730548
A23: 0 | B23: =DATA!C23 -> 528 | C23: =DATA!I23 -> 4 | D23: =DATA!M23 -> 0 | G23: NumOfProducts | H23: -0.0085498778 | I23: 0.020094146 | J23: -0.42549098 | K23: 0.67066372 | L23: -0.048030212 | M23: 0.030930457 | N23: -0.048030212 | O23: 0.030930457
A24: 1 | B24: =DATA!C24 -> 524 | C24: =DATA!I24 -> 4 | D24: =DATA!M24 -> 1
A25: 0 | B25: =DATA!C25 -> 443 | C25: =DATA!I25 -> 2 | D25: =DATA!M25 -> 0
A26: 0 | B26: =DATA!C26 -> 464 | C26: =DATA!I26 -> 2 | D26: =DATA!M26 -> 0
A27: 1 | B27: =DATA!C27 -> 511 | C27: =DATA!I27 -> 2 | D27: =DATA!M27 -> 0
A28: 1 | B28: =DATA!C28 -> 618 | C28: =DATA!I28 -> 3 | D28: =DATA!M28 -> 1
A29: 0 | B29: =DATA!C29 -> 574 | C29: =DATA!I29 -> 3 | D29: =DATA!M29 -> 0
A30: 1 | B30: =DATA!C30 -> 583 | C30: =DATA!I30 -> 2 | D30: =DATA!M30 -> 1
A31: 0 | B31: =DATA!C31 -> 686 | C31: =DATA!I31 -> 4 | D31: =DATA!M31 -> 1
A32: 0 | B32: =DATA!C32 -> 416 | C32: =DATA!I32 -> 3 | D32: =DATA!M32 -> 1
A33: 1 | B33: =DATA!C33 -> 806 | C33: =DATA!I33 -> 4 | D33: =DATA!M33 -> 1
A34: 1 | B34: =DATA!C34 -> 849 | C34: =DATA!I34 -> 1 | D34: =DATA!M34 -> 1
A35: 0 | B35: =DATA!C35 -> 475 | C35: =DATA!I35 -> 1 | D35: =DATA!M35 -> 0
... A500: 1 | B500: =DATA!C500 -> 393 | C500: =DATA!I500 -> 3 | D500: =DATA!M500 -> 1

Sheet RA3
A1: {=DATA!G1:G500} -> Tenure | B1: =DATA!H1 -> Balance | C1: =DATA!L1 -> EstimatedSalary | D1: =DATA!M1 -> Churn
A2: 7 | B2: =DATA!H2 -> 119274.87 | C2: =DATA!L2 -> 107886.77 | D2: =DATA!M2 -> 0
A3: 3 | B3: =DATA!H3 -> 203737.4 | C3: =DATA!L3 -> 52848.11 | D3: =DATA!M3 -> 0
A4: 6 | B4: =DATA!H4 -> 146780.5 | C4: =DATA!L4 -> 94395.02 | D4: =DATA!M4 -> 0 | G4: SUMMARY OUTPUT
A5: 0 | B5: =DATA!H5 -> 23572.03 | C5: =DATA!L5 -> 146739.55 | D5: =DATA!M5 -> 0
A6: 2 | B6: =DATA!H6 -> 7463.43 | C6: =DATA!L6 -> 16036.55 | D6: =DATA!M6 -> 0 | G6: Regression Statistics
A7: 0 | B7: =DATA!H7 -> 127812.9 | C7: =DATA!L7 -> 65189.1 | D7: =DATA!M7 -> 0 | G7: Multiple R | H7: 0.067935437
A8: 10 | B8: =DATA!H8 -> 136164.96 | C8: =DATA!L8 -> 135962.88 | D8: =DATA!M8 -> 0 | G8: R Square | H8: 0.0046152236
A9: 5 | B9: =DATA!H9 -> 204042.02 | C9: =DATA!L9 -> 92581.54 | D9: =DATA!M9 -> 1 | G9: Adjusted R Square | H9: -0.0014174115
A10: 1 | B10: =DATA!H10 -> 182609.21 | C10: =DATA!L10 -> 141848.51 | D10: =DATA!M10 -> 1 | G10: Standard Error | H10: 0.49881558
A11: 7 | B11: =DATA!H11 -> 56345.73 | C11: =DATA!L11 -> 143065.1 | D11: =DATA!M11 -> 1 | G11: Observations | H11: 499
A12: 10 | B12: =DATA!H12 -> 198399.26 | C12: =DATA!L12 -> 125839.96 | D12: =DATA!M12 -> 1
A13: 3 | B13: =DATA!H13 -> 157278.91 | C13: =DATA!L13 -> 58708.71 | D13: =DATA!M13 -> 1 | G13: ANOVA
A14: 2 | B14: =DATA!H14 -> 58317.75 | C14: =DATA!L14 -> 13740.96 | D14: =DATA!M14 -> 0 | H14: df | I14: SS | J14: MS | K14: F | L14: Significance F
A15: 3 | B15: =DATA!H15 -> 128968.35 | C15: =DATA!L15 -> 143532.82 | D15: =DATA!M15 -> 1 | G15: Regression | H15: 3 | I15: 0.57106686 | J15: 0.19035562 | K15: 0.76504273 | L15: 0.51402952
A16: 2 | B16: =DATA!H16 -> 60006.91 | C16: =DATA!L16 -> 38571.28 | D16: =DATA!M16 -> 0 | G16: Residual | H16: 495 | I16: 123.1644 | J16: 0.24881698
A17: 3 | B17: =DATA!H17 -> 180430.72 | C17: =DATA!L17 -> 43961.45 | D17: =DATA!M17 -> 1 | G17: Total | H17: 498 | I17: 123.73547
A18: 7 | B18: =DATA!H18 -> 75466.39 | C18: =DATA!L18 -> 103226.64 | D18: =DATA!M18 -> 1
A19: 7 | B19: =DATA!H19 -> 124186.11 | C19: =DATA!L19 -> 108305.55 | D19: =DATA!M19 -> 0 | H19: Coefficients | I19: Standard Error | J19: t Stat | K19: P-value | L19: Lower 95% | M19: Upper 95% | N19: Lower 95.0% | O19: Upper 95.0%
A20: 1 | B20: =DATA!H20 -> 224549.07 | C20: =DATA!L20 -> 144262.57 | D20: =DATA!M20 -> 1 | G20: Intercept | H20: 0.44905214 | I20: 0.075317609 | J20: 5.9621135 | K20: 4.7384193e-09 | L20: 0.30107051 | M20: 0.59703376 | N20: 0.30107051 | O20: 0.59703376
A21: 4 | B21: =DATA!H21 -> 246840.35 | C21: =DATA!L21 -> 93337.31 | D21: =DATA!M21 -> 0 | G21: Tenure | H21: 0.0087474674 | I21: 0.0069403758 | J21: 1.2603737 | K21: 0.20812838 | L21: -0.0048887608 | M21: 0.022383696 | N21: -0.0048887608 | O21: 0.022383696
A22: 6 | B22: =DATA!H22 -> 239474.66 | C22: =DATA!L22 -> 71646.19 | D22: =DATA!M22 -> 1 | G22: Balance | H22: 1.1563176e-07 | I22: 3.1183674e-07 | J22: 0.37080867 | K22: 0.71093868 | L22: -4.9705507e-07 | M22: 7.283186e-07 | N22: -4.9705507e-07 | O22: 7.283186e-07
A23: 10 | B23: =DATA!H23 -> 192616.6 | C23: =DATA!L23 -> 27413.39 | D23: =DATA!M23 -> 0 | G23: EstimatedSalary | H23: 4.3827306e-07 | I23: 5.4821465e-07 | J23: 0.79945521 | K23: 0.42440996 | L23: -6.3884154e-07 | M23: 1.5153877e-06 | N23: -6.3884154e-07 | O23: 1.5153877e-06
A24: 7 | B24: =DATA!H24 -> 34050.82 | C24: =DATA!L24 -> 130037.45 | D24: =DATA!M24 -> 1
A25: 0 | B25: =DATA!H25 -> 116986.77 | C25: =DATA!L25 -> 16197.08 | D25: =DATA!M25 -> 0
A26: 0 | B26: =DATA!H26 -> 242071.38 | C26: =DATA!L26 -> 129312.08 | D26: =DATA!M26 -> 0
A27: 6 | B27: =DATA!H27 -> 88252.4 | C27: =DATA!L27 -> 57083.95 | D27: =DATA!M27 -> 0
A28: 4 | B28: =DATA!H28 -> 39874.14 | C28: =DATA!L28 -> 137124.11 | D28: =DATA!M28 -> 1
A29: 4 | B29: =DATA!H29 -> 47828.14 | C29: =DATA!L29 -> 129087.2 | D29: =DATA!M29 -> 0
A30: 10 | B30: =DATA!H30 -> 137337.08 | C30: =DATA!L30 -> 107849.47 | D30: =DATA!M30 -> 1
A31: 5 | B31: =DATA!H31 -> 5425.45 | C31: =DATA!L31 -> 82220.31 | D31: =DATA!M31 -> 1
A32: 1 | B32: =DATA!H32 -> 192565.36 | C32: =DATA!L32 -> 106833.18 | D32: =DATA!M32 -> 1
A33: 10 | B33: =DATA!H33 -> 98142.26 | C33: =DATA!L33 -> 88655.49 | D33: =DATA!M33 -> 1
A34: 2 | B34: =DATA!H34 -> 55839.55 | C34: =DATA!L34 -> 45305.66 | D34: =DATA!M34 -> 1
A35: 6 | B35: =DATA!H35 -> 72899.17 | C35: =DATA!L35 -> 90761.77 | D35: =DATA!M35 -> 0
... A500: 9 | B500: =DATA!H500 -> 189955.55 | C500: =DATA!L500 -> 85565.14 | D500: =DATA!M500 -> 1

Sheet Final RA
A1: {=DATA!S1:S500} -> Gender Category | B1: =DATA!M1 -> Churn
A2: 1 | B2: =DATA!M2 -> 0
A3: 2 | B3: =DATA!M3 -> 0 | D3: SUMMARY OUTPUT
A4: 1 | B4: =DATA!M4 -> 0
A5: 2 | B5: =DATA!M5 -> 0 | D5: Regression Statistics
A6: 2 | B6: =DATA!M6 -> 0 | D6: Multiple R | E6: 0.09368854
A7: 2 | B7: =DATA!M7 -> 0 | D7: R Square | E7: 0.0087775424
A8: 2 | B8: =DATA!M8 -> 0 | D8: Adjusted R Square | E8: 0.0067831311
A9: 1 | B9: =DATA!M9 -> 1 | D9: Standard Error | E9: 0.49676899
A10: 2 | B10: =DATA!M10 -> 1 | D10: Observations | E10: 499
A11: 2 | B11: =DATA!M11 -> 1
A12: 2 | B12: =DATA!M12 -> 1 | D12: ANOVA
A13: 1 | B13: =DATA!M13 -> 1 | E13: df | F13: SS | G13: MS | H13: F | I13: Significance F
A14: 2 | B14: =DATA!M14 -> 0 | D14: Regression | E14: 1 | F14: 1.0860933 | G14: 1.0860933 | H14: 4.4010692 | I14: 0.036420765
A15: 1 | B15: =DATA!M15 -> 1 | D15: Residual | E15: 497 | F15: 122.64938 | G15: 0.24677943
A16: 1 | B16: =DATA!M16 -> 0 | D16: Total | E16: 498 | F16: 123.73547
A17: 2 | B17: =DATA!M17 -> 1
A18: 1 | B18: =DATA!M18 -> 1 | E18: Coefficients | F18: Standard Error | G18: t Stat | H18: P-value | I18: Lower 95% | J18: Upper 95% | K18: Lower 95.0% | L18: Upper 95.0%
A19: 1 | B19: =DATA!M19 -> 0 | D19: Intercept | E19: 0.68672199 | F19: 0.071080473 | G19: 9.6611906 | H19: 2.3739127e-20 | I19: 0.54706673 | J19: 0.82637725 | K19: 0.54706673 | L19: 0.82637725
A20: 2 | B20: =DATA!M20 -> 1 | D20: Gender Category | E20: -0.093360996 | F20: 0.044502702 | G20: -2.0978725 | H20: 0.036420765 | I20: -0.18079762 | J20: -0.0059243741 | K20: -0.18079762 | L20: -0.0059243741
A21: 2 | B21: =DATA!M21 -> 0
A22: 1 | B22: =DATA!M22 -> 1
A23: 2 | B23: =DATA!M23 -> 0 | D23: =F23+(H23*J23) -> 0.5 | E23: = | F23: =E19 -> 0.68672199 | G23: + | H23: =E20 -> -0.093360996 | I23: * | J23: 2
A24: 1 | B24: =DATA!M24 -> 1
A25: 2 | B25: =DATA!M25 -> 0
A26: 2 | B26: =DATA!M26 -> 0
A27: 2 | B27: =DATA!M27 -> 0
A28: 1 | B28: =DATA!M28 -> 1
A29: 1 | B29: =DATA!M29 -> 0
A30: 1 | B30: =DATA!M30 -> 1
A31: 2 | B31: =DATA!M31 -> 1
A32: 1 | B32: =DATA!M32 -> 1
A33: 2 | B33: =DATA!M33 -> 1
A34: 2 | B34: =DATA!M34 -> 1
A35: 1 | B35: =DATA!M35 -> 0
... A500: 1 | B500: =DATA!M500 -> 1

Sheet Test
A1: {=DATA!S1:S500} -> Gender Category | B1: =DATA!M1 -> Churn | H1: Gender | I1: =DATA!M1 -> Churn
A2: 1 | B2: =DATA!M2 -> 0 | E2: Gender Category | F2: Churn | H2: Female | I2: =DATA!M3 -> 0 | K2: t-Test: Two-Sample Assuming Equal Variances
A3: 2 | B3: =DATA!M3 -> 0 | D3: Gender Category | E3: 1 | H3: Female | I3: =DATA!M5 -> 0
A4: 1 | B4: =DATA!M4 -> 0 | D4: Churn | E4: -0.15434817 | F4: 1 | H4: Female | I4: =DATA!M6 -> 0 | L4: Male | M4: Female
A5: 2 | B5: =DATA!M5 -> 0 | H5: Female | I5: =DATA!M7 -> 0 | K5: Mean | L5: 0.593361 | M5: 0.5
A6: 2 | B6: =DATA!M6 -> 0 | H6: Female | I6: =DATA!M8 -> 0 | K6: Variance | L6: 0.24228907 | M6: 0.25097276
A7: 2 | B7: =DATA!M7 -> 0 | D7: Male | E7: Female | H7: Female | I7: =DATA!M10 -> 1 | K7: Observations | L7: 241 | M7: 258
A8: 2 | B8: =DATA!M8 -> 0 | D8: 0 | E8: 0 | H8: Female | I8: =DATA!M11 -> 1 | K8: Pooled Variance | L8: 0.24677943
A9: 1 | B9: =DATA!M9 -> 1 | D9: 0 | E9: 0 | H9: Female | I9: =DATA!M12 -> 1 | K9: Hypothesized Mean Difference | L9: 0
A10: 2 | B10: =DATA!M10 -> 1 | D10: 1 | E10: 0 | H10: Female | I10: =DATA!M14 -> 0 | K10: df | L10: 497
A11: 2 | B11: =DATA!M11 -> 1 | D11: 1 | E11: 0 | H11: Female | I11: =DATA!M17 -> 1 | K11: t Stat | L11: 2.0978725
A12: 2 | B12: =DATA!M12 -> 1 | D12: 1 | E12: 0 | H12: Female | I12: =DATA!M20 -> 1 | K12: P(T<=t) one-tail | L12: 0.018210383
A13: 1 | B13: =DATA!M13 -> 1 | D13: 0 | E13: 1 | H13: Female | I13: =DATA!M21 -> 0 | K13: t Critical one-tail | L13: 1.6479253
A14: 2 | B14: =DATA!M14 -> 0 | D14: 1 | E14: 1 | H14: Female | I14: =DATA!M23 -> 0 | K14: P(T<=t) two-tail | L14: 0.036420765
A15: 1 | B15: =DATA!M15 -> 1 | D15: 0 | E15: 1 | H15: Female | I15: =DATA!M25 -> 0 | K15: t Critical two-tail | L15: 1.9647486
A16: 1 | B16: =DATA!M16 -> 0 | D16: 1 | E16: 0 | H16: Female | I16: =DATA!M26 -> 0
A17: 2 | B17: =DATA!M17 -> 1 | D17: 1 | E17: 1 | H17: Female | I17: =DATA!M27 -> 0
A18: 1 | B18: =DATA!M18 -> 1 | D18: 1 | E18: 1 | H18: Female | I18: =DATA!M31 -> 1
A19: 1 | B19: =DATA!M19 -> 0 | D19: 0 | E19: 0 | H19: Female | I19: =DATA!M33 -> 1
A20: 2 | B20: =DATA!M20 -> 1 | D20: 1 | E20: 0 | H20: Female | I20: =DATA!M34 -> 1
A21: 2 | B21: =DATA!M21 -> 0 | D21: 1 | E21: 0 | H21: Female | I21: =DATA!M36 -> 1
A22: 1 | B22: =DATA!M22 -> 1 | D22: 0 | E22: 0 | H22: Female | I22: =DATA!M38 -> 0
A23: 2 | B23: =DATA!M23 -> 0 | D23: 1 | E23: 0 | H23: Female | I23: =DATA!M40 -> 1
A24: 1 | B24: =DATA!M24 -> 1 | D24: 0 | E24: 1 | H24: Female | I24: =DATA!M41 -> 0
A25: 2 | B25: =DATA!M25 -> 0 | D25: 1 | E25: 1 | H25: Female | I25: =DATA!M44 -> 1
A26: 2 | B26: =DATA!M26 -> 0 | D26: 0 | E26: 1 | H26: Female | I26: =DATA!M46 -> 0
A27: 2 | B27: =DATA!M27 -> 0 | D27: 0 | E27: 1 | H27: Female | I27: =DATA!M47 -> 1
A28: 1 | B28: =DATA!M28 -> 1 | D28: 0 | E28: 0 | H28: Female | I28: =DATA!M48 -> 0
